---
title: Ausnahmebehandlung (Task Parallel Library)
description: Erfahren Sie mehr über die Ausnahmebehandlung mit der Task Parallel Library (TPL) in .NET. Unter anderem werden geschachtelte aggregierte Ausnahmen, innere Ausnahmen und nicht überwachte Taskausnahmen behandelt.
ms.date: 04/20/2020
dev_langs:
- csharp
- vb
helpviewer_keywords:
- tasks, exceptions
ms.assetid: beb51e50-9061-4d3d-908c-56a4f7c2e8c1
ms.openlocfilehash: fd16fd4263c092f8678589e1a8dd9544955e798a
ms.sourcegitcommit: 965a5af7918acb0a3fd3baf342e15d511ef75188
ms.translationtype: HT
ms.contentlocale: de-DE
ms.lasthandoff: 11/18/2020
ms.locfileid: "94827333"
---
# <a name="exception-handling-task-parallel-library"></a>Ausnahmebehandlung (Task Parallel Library)

Nicht behandelte Ausnahmen, die von innerhalb einer Aufgabe ausgeführtem Benutzercode ausgelöst werden, werden zurück zum aufrufenden Thread geleitet. Hiervon ausgenommen sind bestimmte Szenarios, die weiter unten in diesem Thema beschrieben werden. Ausnahmen werden weitergegeben, wenn Sie eine der statischen oder instanzbasierten <xref:System.Threading.Tasks.Task.Wait%2A?displayProperty=nameWithType>-Methoden verwenden. Zur Behandlung dieser Ausnahmen schließen Sie den Aufruf in eine `try`/`catch`-Anweisung ein. Wenn eine Aufgabe das übergeordnete Element angefügter untergeordneter Aufgaben ist oder wenn Sie auf mehrere Aufgaben warten, können mehrere Ausnahmen ausgelöst werden.

Um alle Ausnahmen zurück an den aufrufenden Thread zu leiten, schließt die Aufgabeninfrastruktur diese in eine <xref:System.AggregateException> -Instanz ein. Die <xref:System.AggregateException> -Ausnahme verfügt über eine <xref:System.AggregateException.InnerExceptions%2A> -Eigenschaft, die aufgelistet werden kann, um alle ursprünglich ausgelösten Ausnahmen zu analysieren und jede Ausnahme einzeln zu behandeln (bzw. nicht zu behandeln). Sie können die ursprünglichen Ausnahmen mithilfe der <xref:System.AggregateException.Handle%2A?displayProperty=nameWithType> -Methode ebenfalls behandeln.

Auch wenn nur eine Ausnahme ausgelöst wurde, wird diese in eine <xref:System.AggregateException> -Ausnahme eingeschlossen, wie im nachfolgenden Beispiel veranschaulicht.

[!code-csharp[TPL_Exceptions#21](../../../samples/snippets/csharp/VS_Snippets_Misc/tpl_exceptions/cs/handling21.cs#21)]
[!code-vb[TPL_Exceptions#21](../../../samples/snippets/visualbasic/VS_Snippets_Misc/tpl_exceptions/vb/handling21.vb#21)]

Unbehandeltes Ausnahmen vermeiden Sie, indem Sie nur die <xref:System.AggregateException> erfassen und die inneren Ausnahmen nicht beachten. Hiervon wird jedoch abgeraten, da dies dem Erfassen des grundlegenden <xref:System.Exception> -Typs in nicht parallelen Szenarios entspricht. Wenn Sie eine Ausnahme erfassen, ohne Maßnahmen zu deren Behandlung zu ergreifen, weist das Programm ggf. einen unbestimmten Zustand auf.

Wenn Sie die <xref:System.Threading.Tasks.Task.Wait%2A?displayProperty=nameWithType>-Methode nicht aufrufen möchten, um auf den Abschluss einer Aufgabe zu warten, können Sie auch die <xref:System.AggregateException>-Ausnahme der <xref:System.Threading.Tasks.Task.Exception%2A>-Eigenschaft der Aufgabe abrufen, wie im folgenden Beispiel dargestellt. Weitere Informationen finden Sie im Abschnitt [Beachten von Ausnahmen mit der Task.Exception-Eigenschaft](#observing-exceptions-by-using-the-taskexception-property) dieses Themas.

[!code-csharp[TPL_Exceptions#29](../../../samples/snippets/csharp/VS_Snippets_Misc/tpl_exceptions/cs/handling22.cs#29)]
[!code-vb[TPL_Exceptions#29](../../../samples/snippets/visualbasic/VS_Snippets_Misc/tpl_exceptions/vb/handling22.vb#29)]

Wenn Sie nicht auf eine Aufgabe warten, die eine Ausnahme weitergibt, oder auf deren <xref:System.Threading.Tasks.Task.Exception%2A> -Eigenschaft zugreifen, wird die Ausnahme entsprechend der .NET-Ausnahmerichtlinie eskaliert, sofern die Aufgabe der Garbage Collection unterliegt.

Wenn Ausnahmen mittels Bubbling wieder an den Verbindungsthread übergeben werden können, ist es möglich, dass eine Aufgabe nach dem Auslösen der Ausnahme weiterhin einige Elemente verarbeitet.

> [!NOTE]
> Wenn "Nur eigenen Code" aktiviert ist, unterbricht Visual Studio die Ausführung in einigen Fällen in der Zeile, die die Ausnahme auslöst, und eine Fehlermeldung zu einer nicht vom Benutzercode behandelten Ausnahme wird angezeigt. Dieser Fehler hat keine Auswirkungen. Sie können F5 drücken, um den Vorgang fortzusetzen. In diesem Fall wird das in den folgenden Beispielen veranschaulichte Ausnahmebehandlungsverhalten angewendet. Um zu verhindern, dass Visual Studio die Ausführung beim ersten Fehler unterbricht, deaktivieren Sie das Kontrollkästchen **Nur eigenen Code** unter **Extras, Optionen, Debugging, Allgemein**.

## <a name="attached-child-tasks-and-nested-aggregateexceptions"></a>Angefügte untergeordnete Aufgaben und geschachtelte AggregateExceptions

Wenn eine Aufgabe über eine angefügte untergeordnete Aufgabe verfügt, die eine Ausnahme auslöst, wird diese Ausnahme in <xref:System.AggregateException> eingeschlossen, bevor sie an die übergeordnete Aufgabe weitergegeben wird, die diese Ausnahme in eine eigene <xref:System.AggregateException> einschließt und sie anschließend an den aufrufenden Thread zurückgibt. In solchen Fällen enthält die <xref:System.AggregateException.InnerExceptions%2A>-Eigenschaft der <xref:System.AggregateException>-Ausnahme, die bei den Methoden <xref:System.Threading.Tasks.Task.Wait%2A?displayProperty=nameWithType>, <xref:System.Threading.Tasks.Task.WaitAny%2A> oder <xref:System.Threading.Tasks.Task.WaitAll%2A> abgefangen wird, eine oder mehrere <xref:System.AggregateException>-Instanzen und nicht die ursprünglichen Ausnahmen, die den Fehler verursacht haben. Um eine Iteration geschachtelter <xref:System.AggregateException>-Ausnahmen zu vermeiden, können Sie mit der <xref:System.AggregateException.Flatten%2A>-Methode alle geschachtelten <xref:System.AggregateException>-Ausnahmen entfernen, sodass die <xref:System.AggregateException.InnerExceptions%2A?displayProperty=nameWithType>-Eigenschaft die ursprünglichen Ausnahmen enthält. Im folgenden Beispiel werden geschachtelte <xref:System.AggregateException> -Instanzen vereinfacht und in nur einen Schleife behandelt.

[!code-csharp[TPL_Exceptions#22](../../../samples/snippets/csharp/VS_Snippets_Misc/tpl_exceptions/cs/flatten2.cs#22)]
[!code-vb[TPL_Exceptions#22](../../../samples/snippets/visualbasic/VS_Snippets_Misc/tpl_exceptions/vb/flatten2.vb#22)]

Sie können auch die <xref:System.AggregateException.Flatten%2A?displayProperty=nameWithType>-Methode verwenden, um die inneren Ausnahmen von mehreren <xref:System.AggregateException>-Instanzen erneut auszulösen, die von mehreren Aufgaben in einer einzelnen <xref:System.AggregateException>-Instanz ausgelöst wurden, wie im folgenden Beispiel gezeigt.

[!code-csharp[TPL_Exceptions#13](../../../samples/snippets/csharp/VS_Snippets_Misc/tpl_exceptions/cs/taskexceptions2.cs#13)]
[!code-vb[TPL_Exceptions#13](../../../samples/snippets/visualbasic/VS_Snippets_Misc/tpl_exceptions/vb/taskexceptions2.vb#13)]

## <a name="exceptions-from-detached-child-tasks"></a>Ausnahmen bei getrennten untergeordneten Aufgaben

Standardmäßig werden untergeordnete Aufgaben als getrennte Aufgaben erstellt. Von getrennten Aufgaben ausgelöste Ausnahmen müssen in der unmittelbar übergeordneten Aufgabe behandelt oder erneut ausgelöst werden. Sie werden nicht auf die gleiche Weise wie angefügte untergeordnete Aufgaben an den aufrufenden Thread zurück geleitet. Das übergeordnete Element der höchsten Ebene kann eine Ausnahme von einem getrennten untergeordneten Element manuell erneut auslösen, sodass diese in eine <xref:System.AggregateException> eingeschlossen und an den aufrufenden Thread zurück geleitet wird.

[!code-csharp[TPL_Exceptions#23](../../../samples/snippets/csharp/VS_Snippets_Misc/tpl_exceptions/cs/detached21.cs#23)]
[!code-vb[TPL_Exceptions#23](../../../samples/snippets/visualbasic/VS_Snippets_Misc/tpl_exceptions/vb/detached21.vb#23)]

Selbst wenn Sie mithilfe einer Fortsetzung eine Ausnahme in einer untergeordneten Aufgabe beachten, muss die Ausnahme dennoch von der übergeordneten Aufgabe beachtet werden.

## <a name="exceptions-that-indicate-cooperative-cancellation"></a>Ausnahmen mit kooperativem Abbruch

Wenn Benutzercode in einer Aufgabe auf eine Abbruchanforderung reagiert, besteht das korrekte Verfahren darin, dass eine <xref:System.OperationCanceledException> ausgelöst wird, die in dem Abbruchtoken, in dem die Anforderung übermittelt wurde, übergeben wird. Bevor die Ausnahme weitergeleitet wird, vergleicht die Aufgabeninstanz das Token in der Ausnahme mit dem Token, das beim Erstellen an sie übergeben wurde. Stimmen beide Token überein, gibt die Aufgabe eine <xref:System.Threading.Tasks.TaskCanceledException> weiter, die in die <xref:System.AggregateException>eingeschlossen ist. Diese ist zu sehen, wenn die inneren Ausnahmen analysiert werden. Wenn der aufrufende Thread jedoch nicht auf die Aufgabe wartet, wird diese Ausnahme nicht weitergegeben. Weitere Informationen finden Sie unter [Aufgabenabbruch](task-cancellation.md).

[!code-csharp[TPL_Exceptions#4](../../../samples/snippets/csharp/VS_Snippets_Misc/tpl_exceptions/cs/exceptions.cs#4)]
[!code-vb[TPL_Exceptions#4](../../../samples/snippets/visualbasic/VS_Snippets_Misc/tpl_exceptions/vb/tpl_exceptions.vb#4)]

## <a name="using-the-handle-method-to-filter-inner-exceptions"></a>Filtern von inneren Ausnahmen mithilfe der Handle-Methode

Mit der <xref:System.AggregateException.Handle%2A?displayProperty=nameWithType> -Methode können Sie Ausnahmen filtern, die ohne weitere Logik als "behandelt" definiert werden können. Im Benutzerdelegaten, der an die <xref:System.AggregateException.Handle%28System.Func%7BSystem.Exception%2CSystem.Boolean%7D%29?displayProperty=nameWithType> -Methode weitergegeben wird, können Sie den Ausnahmetyp, seine <xref:System.Exception.Message%2A> -Eigenschaft oder beliebige andere Informationen analysieren und ermitteln, ob die Ausnahme keine Auswirkungen zeigt. Alle Ausnahmen, für die der Delegat `false` zurückgibt, werden in einer neuen <xref:System.AggregateException>-Instanz erneut ausgelöst, sobald die <xref:System.AggregateException.Handle%2A?displayProperty=nameWithType>-Methode zurückkehrt.

Das folgende Beispiel ist zum ersten Beispiel dieses Themas funktional äquivalent, das jede Ausnahme in der <xref:System.AggregateException.InnerExceptions%2A?displayProperty=nameWithType>-Auflistung untersucht.  Dieser Ausnahmehandler ruft stattdessen das <xref:System.AggregateException.Handle%2A?displayProperty=nameWithType>-Methodenobjekt für jede Ausnahme auf und löst nur die Ausnahmen erneut aus, die keine `CustomException`-Instanzen sind.

[!code-csharp[TPL_Exceptions#26](../../../samples/snippets/csharp/VS_Snippets_Misc/tpl_exceptions/cs/handlemethod21.cs#26)]
[!code-vb[TPL_Exceptions#26](../../../samples/snippets/visualbasic/VS_Snippets_Misc/tpl_exceptions/vb/handlemethod21.vb#26)]

Nachfolgend finden Sie ein vollständigeres Beispiel, das die <xref:System.AggregateException.Handle%2A?displayProperty=nameWithType>-Methode verwendet, um beim Auflisten von Dateien für eine <xref:System.UnauthorizedAccessException>-Ausnahme eine besondere Behandlung zu bieten.

[!code-csharp[TPL_Exceptions#12](../../../samples/snippets/csharp/VS_Snippets_Misc/tpl_exceptions/cs/taskexceptions.cs#12)]
[!code-vb[TPL_Exceptions#12](../../../samples/snippets/visualbasic/VS_Snippets_Misc/tpl_exceptions/vb/taskexceptions.vb#12)]

## <a name="observing-exceptions-by-using-the-taskexception-property"></a>Berücksichtigen von Ausnahmen mit der Task.Exception-Eigenschaft

Wenn eine Aufgabe mit einem <xref:System.Threading.Tasks.TaskStatus.Faulted?displayProperty=nameWithType> -Zustand abgeschlossen wird, kann die zugehörige <xref:System.Threading.Tasks.Task.Exception%2A> -Eigenschaft analysiert werden, um die spezifische Ausnahme zu ermitteln, die den Fehler verursacht hat. Eine gute Möglichkeit, die <xref:System.Threading.Tasks.Task.Exception%2A> -Eigenschaft zu beachten, ist eine Fortsetzung, die nur bei einem Fehler in der vorausgehenden Aufgabe ausgeführt wird, wie im folgenden Beispiel gezeigt.

[!code-csharp[TPL_Exceptions#27](../../../samples/snippets/csharp/VS_Snippets_Misc/tpl_exceptions/cs/exceptionprop21.cs#27)]
[!code-vb[TPL_Exceptions#27](../../../samples/snippets/visualbasic/VS_Snippets_Misc/tpl_exceptions/vb/exceptionprop21.vb#27)]

In einer aussagekräftigen Anwendung würde der Fortsetzungsdelegat ausführliche Informationen zu der Ausnahme protokollieren und möglicherweise neue Tasks erzeugen, um nach der Ausnahme fortzufahren. Wenn bei einem Task ein Fehler auftritt, wird die Ausnahme durch die folgenden Ausdrücke ausgelöst:

- `await task`
- `task.Wait()`
- `task.Result`
- `task.GetAwaiter().GetResult()`

Verwenden Sie eine [`try-catch`](../../csharp/language-reference/keywords/try-catch.md)-Anweisung, um ausgelöste Ausnahmen zu verarbeiten und zu beobachten. Sie können auch die Ausnahme beobachten, indem Sie auf die <xref:System.Threading.Tasks.Task.Exception%2A?displayProperty=nameWithType>-Eigenschaft zugreifen.

## <a name="unobservedtaskexception-event"></a>UnobservedTaskException-Ereignis

In einigen Szenarien können häufig Ausnahmen ohne Auswirkungen auftreten (z. B. wenn Sie nicht vertrauenswürdige Plug-Ins hosten), und es kann schwierig sein, alle Ausnahmen manuell zu überwachen. In diesen Fällen können Sie das <xref:System.Threading.Tasks.TaskScheduler.UnobservedTaskException?displayProperty=nameWithType> -Ereignis behandeln. Mit der an den Handler übergebenen <xref:System.Threading.Tasks.UnobservedTaskExceptionEventArgs?displayProperty=nameWithType> -Instanz kann verhindert werden, dass die nicht überwachte Ausnahme wieder an den Verbindungsthread übergeben wird.

## <a name="see-also"></a>Siehe auch

- [Task Parallel Library (TPL)](task-parallel-library-tpl.md)
